[4m>>>> Executing external compose provider "/usr/local/bin/docker-compose". Please refer to the documentation for details. <<<<

[0mSending build context to Docker daemon  26.01kB
STEP 1/18: FROM osrf/ros:humble-desktop
STEP 2/18: ENV DEBIAN_FRONTEND=noninteractive
--> Using cache b73207ca781ecdd216ed9fe41aebd949876ed3bd486828c433df35a4bf252795
--> b73207ca781e
STEP 3/18: RUN apt-get update     && apt-get install -y --no-install-recommends gazebo     && rm -rf /var/lib/apt/lists/*
--> Using cache f6584624ead4e237c525eea0de045be8bafe94e8f1ea27ae3586f8f80792b062
--> f6584624ead4
STEP 4/18: RUN apt-get install -y curl gnupg2 lsb-release
--> Using cache ffd1b1a86b64c6061c793a4de328db7a8a2326fdd073127567e554d543eb1c8d
--> ffd1b1a86b64
STEP 5/18: RUN curl -sSL https://raw.githubusercontent.com/ros/rosdistro/master/ros.key  -o /usr/share/keyrings/ros-archive-keyring.gpg     && echo "deb [arch=$(dpkg --print-architecture) signed-by=/usr/share/keyrings/ros-archive-keyring.gpg] http://packages.ros.org/ros2/ubuntu $(lsb_release -sc) main" | tee -a /etc/apt/sources.list.d/ros2.list     && apt-get update     && apt-get install -y     ros-humble-gazebo*     ros-humble-cartographer     ros-humble-cartographer-ros     ros-humble-navigation2     ros-humble-nav2-bringup     ros-humble-dynamixel-sdk     ros-humble-turtlebot3-msgs     ros-humble-turtlebot3
--> Using cache 7627608da8b90ee24310ec40967e578b52cab8ab5638182deafc3bbd18a31dda
--> 7627608da8b9
STEP 6/18: RUN echo 'export ROS_DOMAIN_ID=30 #TURTLEBOT3' >> ~/.bashrc
--> Using cache efd5b0c01a2fead0a625ecd7499db78e34989f21d260485474b4242c5334042c
--> efd5b0c01a2f
STEP 7/18: RUN apt-get update && apt-get install -y     libjansson-dev     libboost-dev     imagemagick     libtinyxml-dev     mercurial     cmake     build-essential     git
--> Using cache 7babcd6883debf70d7d3861d34f7a6a2d338e2b5d6e7dbcfc196d5b44ac6b265
--> 7babcd6883de
STEP 8/18: ENV NVM_DIR "/root/.nvm"
--> Using cache cef07f679c7849de9d53a4e395cd887a0aa4a499c5768b52ca215461d556dd1e
--> cef07f679c78
STEP 9/18: ENV NODE_VERSION 8.17.0
--> Using cache 5c2332a20ebf0f415a9d190dfa8c893acd3d5612f359c0d4160d405f504d65aa
--> 5c2332a20ebf
STEP 10/18: RUN curl -o- https://raw.githubusercontent.com/nvm-sh/nvm/master/install.sh | bash     && . $NVM_DIR/nvm.sh     && nvm install $NODE_VERSION     && nvm alias default $NODE_VERSION     && nvm use default
--> Using cache aceb5ccb6bef9e44dc57fb69ba099e77503a9b5f231b46382ea8aa6347b3f6e3
--> aceb5ccb6bef
STEP 11/18: ENV NODE_PATH $NVM_DIR/versions/node/v$NODE_VERSION/lib/node_modules
--> Using cache 12ec32571c481a1d24aedc947910260e42bf8e56a68a28bee3c9ff8435da2222
--> 12ec32571c48
STEP 12/18: ENV PATH      $NVM_DIR/versions/node/v$NODE_VERSION/bin:$PATH 
--> Using cache 310cb06c3d705e54895d6f67c2d000a8f65474d8fdfb7edc2d5f68fe1a97cf41
--> 310cb06c3d70
STEP 13/18: RUN cd ~ && git clone https://github.com/osrf/gzweb &&     cd ~/gzweb &&     git checkout gzweb_1.4.1
--> Using cache f0b6406ca9333a64c1828cdd464cdfe54fe0aa47d8f79092730425bc73703cc2
--> f0b6406ca933
STEP 14/18: RUN . /usr/share/gazebo/setup.sh     && . $NVM_DIR/nvm.sh     && cd ~/gzweb    && npm run deploy --- -m
--> Using cache 1af6c5e43bfdfad6940fb1b0ecca403ee4438601af410bed14e641ee77c89f45
--> 1af6c5e43bfd
STEP 15/18: RUN . /usr/share/gazebo/setup.sh && . /opt/ros/humble/setup.sh     && mkdir /root/turtlebot3_ws     && git clone -b humble-devel https://github.com/ROBOTIS-GIT/turtlebot3_simulations.git src     && colcon build --symlink-install
Cloning into 'src'...
Traceback (most recent call last):
  File "<string>", line 1, in <module>
  File "/usr/lib/python3/dist-packages/numpy/distutils/__init__.py", line 24, in <module>
    from . import ccompiler
  File "/usr/lib/python3/dist-packages/numpy/distutils/ccompiler.py", line 9, in <module>
    from distutils.ccompiler import (
ImportError: cannot import name 'compiler_class' from partially initialized module 'distutils.ccompiler' (most likely due to a circular import) (/usr/lib/python3/dist-packages/numpy/distutils/ccompiler.py)
[1.796s] ERROR:colcon.colcon_core.package_identification:Exception in package identification extension 'python_setup_py' in 'lib/python3/dist-packages/numpy': Command '['/usr/bin/python3', '-c', 'import sys;from contextlib import suppress;exec("with suppress(ImportError):    from setuptools.extern.packaging.specifiers    import SpecifierSet");exec("with suppress(ImportError):    from packaging.specifiers import SpecifierSet");from distutils.core import run_setup;dist = run_setup(    \'setup.py\', script_args=(\'--dry-run\',), stop_after=\'config\');skip_keys = (\'cmdclass\', \'distclass\', \'ext_modules\', \'metadata\');data = {    key: value for key, value in dist.__dict__.items()     if (        not key.startswith(\'_\') and         not callable(value) and         key not in skip_keys and         key not in dist.display_option_names    )};data[\'metadata\'] = {    k: v for k, v in dist.metadata.__dict__.items()     if k not in (\'license_files\', \'provides_extras\')};sys.stdout.buffer.write(repr(data).encode(\'utf-8\'))']' returned non-zero exit status 1.
Traceback (most recent call last):
  File "/usr/lib/python3/dist-packages/colcon_core/package_identification/__init__.py", line 142, in _identify
    retval = extension.identify(_reused_descriptor_instance)
  File "/usr/lib/python3/dist-packages/colcon_python_setup_py/package_identification/python_setup_py.py", line 48, in identify
    config = get_setup_information(setup_py)
  File "/usr/lib/python3/dist-packages/colcon_python_setup_py/package_identification/python_setup_py.py", line 241, in get_setup_information
    _setup_information_cache[hashable_env] = _get_setup_information(
  File "/usr/lib/python3/dist-packages/colcon_python_setup_py/package_identification/python_setup_py.py", line 288, in _get_setup_information
    result = subprocess.run(
  File "/usr/lib/python3.10/subprocess.py", line 526, in run
    raise CalledProcessError(retcode, process.args,
subprocess.CalledProcessError: Command '['/usr/bin/python3', '-c', 'import sys;from contextlib import suppress;exec("with suppress(ImportError):    from setuptools.extern.packaging.specifiers    import SpecifierSet");exec("with suppress(ImportError):    from packaging.specifiers import SpecifierSet");from distutils.core import run_setup;dist = run_setup(    \'setup.py\', script_args=(\'--dry-run\',), stop_after=\'config\');skip_keys = (\'cmdclass\', \'distclass\', \'ext_modules\', \'metadata\');data = {    key: value for key, value in dist.__dict__.items()     if (        not key.startswith(\'_\') and         not callable(value) and         key not in skip_keys and         key not in dist.display_option_names    )};data[\'metadata\'] = {    k: v for k, v in dist.metadata.__dict__.items()     if k not in (\'license_files\', \'provides_extras\')};sys.stdout.buffer.write(repr(data).encode(\'utf-8\'))']' returned non-zero exit status 1.

Traceback (most recent call last):
  File "<string>", line 1, in <module>
  File "/usr/lib/python3.10/distutils/core.py", line 225, in run_setup
    raise RuntimeError(("'distutils.core.setup()' was never called -- "
RuntimeError: 'distutils.core.setup()' was never called -- perhaps 'setup.py' is not a Distutils setup script?
[2.063s] ERROR:colcon.colcon_core.package_identification:Exception in package identification extension 'python_setup_py' in 'lib/python3/dist-packages/numpy/compat': Command '['/usr/bin/python3', '-c', 'import sys;from contextlib import suppress;exec("with suppress(ImportError):    from setuptools.extern.packaging.specifiers    import SpecifierSet");exec("with suppress(ImportError):    from packaging.specifiers import SpecifierSet");from distutils.core import run_setup;dist = run_setup(    \'setup.py\', script_args=(\'--dry-run\',), stop_after=\'config\');skip_keys = (\'cmdclass\', \'distclass\', \'ext_modules\', \'metadata\');data = {    key: value for key, value in dist.__dict__.items()     if (        not key.startswith(\'_\') and         not callable(value) and         key not in skip_keys and         key not in dist.display_option_names    )};data[\'metadata\'] = {    k: v for k, v in dist.metadata.__dict__.items()     if k not in (\'license_files\', \'provides_extras\')};sys.stdout.buffer.write(repr(data).encode(\'utf-8\'))']' returned non-zero exit status 1.
Traceback (most recent call last):
  File "/usr/lib/python3/dist-packages/colcon_core/package_identification/__init__.py", line 142, in _identify
    retval = extension.identify(_reused_descriptor_instance)
  File "/usr/lib/python3/dist-packages/colcon_python_setup_py/package_identification/python_setup_py.py", line 48, in identify
    config = get_setup_information(setup_py)
  File "/usr/lib/python3/dist-packages/colcon_python_setup_py/package_identification/python_setup_py.py", line 241, in get_setup_information
    _setup_information_cache[hashable_env] = _get_setup_information(
  File "/usr/lib/python3/dist-packages/colcon_python_setup_py/package_identification/python_setup_py.py", line 288, in _get_setup_information
    result = subprocess.run(
  File "/usr/lib/python3.10/subprocess.py", line 526, in run
    raise CalledProcessError(retcode, process.args,
subprocess.CalledProcessError: Command '['/usr/bin/python3', '-c', 'import sys;from contextlib import suppress;exec("with suppress(ImportError):    from setuptools.extern.packaging.specifiers    import SpecifierSet");exec("with suppress(ImportError):    from packaging.specifiers import SpecifierSet");from distutils.core import run_setup;dist = run_setup(    \'setup.py\', script_args=(\'--dry-run\',), stop_after=\'config\');skip_keys = (\'cmdclass\', \'distclass\', \'ext_modules\', \'metadata\');data = {    key: value for key, value in dist.__dict__.items()     if (        not key.startswith(\'_\') and         not callable(value) and         key not in skip_keys and         key not in dist.display_option_names    )};data[\'metadata\'] = {    k: v for k, v in dist.metadata.__dict__.items()     if k not in (\'license_files\', \'provides_extras\')};sys.stdout.buffer.write(repr(data).encode(\'utf-8\'))']' returned non-zero exit status 1.

Traceback (most recent call last):
  File "<string>", line 1, in <module>
  File "/usr/lib/python3.10/distutils/core.py", line 225, in run_setup
    raise RuntimeError(("'distutils.core.setup()' was never called -- "
RuntimeError: 'distutils.core.setup()' was never called -- perhaps 'setup.py' is not a Distutils setup script?
[2.435s] ERROR:colcon.colcon_core.package_identification:Exception in package identification extension 'python_setup_py' in 'lib/python3/dist-packages/numpy/core': Command '['/usr/bin/python3', '-c', 'import sys;from contextlib import suppress;exec("with suppress(ImportError):    from setuptools.extern.packaging.specifiers    import SpecifierSet");exec("with suppress(ImportError):    from packaging.specifiers import SpecifierSet");from distutils.core import run_setup;dist = run_setup(    \'setup.py\', script_args=(\'--dry-run\',), stop_after=\'config\');skip_keys = (\'cmdclass\', \'distclass\', \'ext_modules\', \'metadata\');data = {    key: value for key, value in dist.__dict__.items()     if (        not key.startswith(\'_\') and         not callable(value) and         key not in skip_keys and         key not in dist.display_option_names    )};data[\'metadata\'] = {    k: v for k, v in dist.metadata.__dict__.items()     if k not in (\'license_files\', \'provides_extras\')};sys.stdout.buffer.write(repr(data).encode(\'utf-8\'))']' returned non-zero exit status 1.
Traceback (most recent call last):
  File "/usr/lib/python3/dist-packages/colcon_core/package_identification/__init__.py", line 142, in _identify
    retval = extension.identify(_reused_descriptor_instance)
  File "/usr/lib/python3/dist-packages/colcon_python_setup_py/package_identification/python_setup_py.py", line 48, in identify
    config = get_setup_information(setup_py)
  File "/usr/lib/python3/dist-packages/colcon_python_setup_py/package_identification/python_setup_py.py", line 241, in get_setup_information
    _setup_information_cache[hashable_env] = _get_setup_information(
  File "/usr/lib/python3/dist-packages/colcon_python_setup_py/package_identification/python_setup_py.py", line 288, in _get_setup_information
    result = subprocess.run(
  File "/usr/lib/python3.10/subprocess.py", line 526, in run
    raise CalledProcessError(retcode, process.args,
subprocess.CalledProcessError: Command '['/usr/bin/python3', '-c', 'import sys;from contextlib import suppress;exec("with suppress(ImportError):    from setuptools.extern.packaging.specifiers    import SpecifierSet");exec("with suppress(ImportError):    from packaging.specifiers import SpecifierSet");from distutils.core import run_setup;dist = run_setup(    \'setup.py\', script_args=(\'--dry-run\',), stop_after=\'config\');skip_keys = (\'cmdclass\', \'distclass\', \'ext_modules\', \'metadata\');data = {    key: value for key, value in dist.__dict__.items()     if (        not key.startswith(\'_\') and         not callable(value) and         key not in skip_keys and         key not in dist.display_option_names    )};data[\'metadata\'] = {    k: v for k, v in dist.metadata.__dict__.items()     if k not in (\'license_files\', \'provides_extras\')};sys.stdout.buffer.write(repr(data).encode(\'utf-8\'))']' returned non-zero exit status 1.

Traceback (most recent call last):
  File "<string>", line 1, in <module>
  File "/usr/lib/python3.10/distutils/core.py", line 215, in run_setup
    exec(f.read(), g)
  File "<string>", line 8, in <module>
ModuleNotFoundError: No module named 'Cython'
[2.791s] ERROR:colcon.colcon_core.package_identification:Exception in package identification extension 'python_setup_py' in 'lib/python3/dist-packages/numpy/core/tests/examples': Command '['/usr/bin/python3', '-c', 'import sys;from contextlib import suppress;exec("with suppress(ImportError):    from setuptools.extern.packaging.specifiers    import SpecifierSet");exec("with suppress(ImportError):    from packaging.specifiers import SpecifierSet");from distutils.core import run_setup;dist = run_setup(    \'setup.py\', script_args=(\'--dry-run\',), stop_after=\'config\');skip_keys = (\'cmdclass\', \'distclass\', \'ext_modules\', \'metadata\');data = {    key: value for key, value in dist.__dict__.items()     if (        not key.startswith(\'_\') and         not callable(value) and         key not in skip_keys and         key not in dist.display_option_names    )};data[\'metadata\'] = {    k: v for k, v in dist.metadata.__dict__.items()     if k not in (\'license_files\', \'provides_extras\')};sys.stdout.buffer.write(repr(data).encode(\'utf-8\'))']' returned non-zero exit status 1.
Traceback (most recent call last):
  File "/usr/lib/python3/dist-packages/colcon_core/package_identification/__init__.py", line 142, in _identify
    retval = extension.identify(_reused_descriptor_instance)
  File "/usr/lib/python3/dist-packages/colcon_python_setup_py/package_identification/python_setup_py.py", line 48, in identify
    config = get_setup_information(setup_py)
  File "/usr/lib/python3/dist-packages/colcon_python_setup_py/package_identification/python_setup_py.py", line 241, in get_setup_information
    _setup_information_cache[hashable_env] = _get_setup_information(
  File "/usr/lib/python3/dist-packages/colcon_python_setup_py/package_identification/python_setup_py.py", line 288, in _get_setup_information
    result = subprocess.run(
  File "/usr/lib/python3.10/subprocess.py", line 526, in run
    raise CalledProcessError(retcode, process.args,
subprocess.CalledProcessError: Command '['/usr/bin/python3', '-c', 'import sys;from contextlib import suppress;exec("with suppress(ImportError):    from setuptools.extern.packaging.specifiers    import SpecifierSet");exec("with suppress(ImportError):    from packaging.specifiers import SpecifierSet");from distutils.core import run_setup;dist = run_setup(    \'setup.py\', script_args=(\'--dry-run\',), stop_after=\'config\');skip_keys = (\'cmdclass\', \'distclass\', \'ext_modules\', \'metadata\');data = {    key: value for key, value in dist.__dict__.items()     if (        not key.startswith(\'_\') and         not callable(value) and         key not in skip_keys and         key not in dist.display_option_names    )};data[\'metadata\'] = {    k: v for k, v in dist.metadata.__dict__.items()     if k not in (\'license_files\', \'provides_extras\')};sys.stdout.buffer.write(repr(data).encode(\'utf-8\'))']' returned non-zero exit status 1.

Traceback (most recent call last):
  File "<string>", line 1, in <module>
  File "/usr/lib/python3.10/distutils/core.py", line 225, in run_setup
    raise RuntimeError(("'distutils.core.setup()' was never called -- "
RuntimeError: 'distutils.core.setup()' was never called -- perhaps 'setup.py' is not a Distutils setup script?
[3.065s] ERROR:colcon.colcon_core.package_identification:Exception in package identification extension 'python_setup_py' in 'lib/python3/dist-packages/numpy/distutils': Command '['/usr/bin/python3', '-c', 'import sys;from contextlib import suppress;exec("with suppress(ImportError):    from setuptools.extern.packaging.specifiers    import SpecifierSet");exec("with suppress(ImportError):    from packaging.specifiers import SpecifierSet");from distutils.core import run_setup;dist = run_setup(    \'setup.py\', script_args=(\'--dry-run\',), stop_after=\'config\');skip_keys = (\'cmdclass\', \'distclass\', \'ext_modules\', \'metadata\');data = {    key: value for key, value in dist.__dict__.items()     if (        not key.startswith(\'_\') and         not callable(value) and         key not in skip_keys and         key not in dist.display_option_names    )};data[\'metadata\'] = {    k: v for k, v in dist.metadata.__dict__.items()     if k not in (\'license_files\', \'provides_extras\')};sys.stdout.buffer.write(repr(data).encode(\'utf-8\'))']' returned non-zero exit status 1.
Traceback (most recent call last):
  File "/usr/lib/python3/dist-packages/colcon_core/package_identification/__init__.py", line 142, in _identify
    retval = extension.identify(_reused_descriptor_instance)
  File "/usr/lib/python3/dist-packages/colcon_python_setup_py/package_identification/python_setup_py.py", line 48, in identify
    config = get_setup_information(setup_py)
  File "/usr/lib/python3/dist-packages/colcon_python_setup_py/package_identification/python_setup_py.py", line 241, in get_setup_information
    _setup_information_cache[hashable_env] = _get_setup_information(
  File "/usr/lib/python3/dist-packages/colcon_python_setup_py/package_identification/python_setup_py.py", line 288, in _get_setup_information
    result = subprocess.run(
  File "/usr/lib/python3.10/subprocess.py", line 526, in run
    raise CalledProcessError(retcode, process.args,
subprocess.CalledProcessError: Command '['/usr/bin/python3', '-c', 'import sys;from contextlib import suppress;exec("with suppress(ImportError):    from setuptools.extern.packaging.specifiers    import SpecifierSet");exec("with suppress(ImportError):    from packaging.specifiers import SpecifierSet");from distutils.core import run_setup;dist = run_setup(    \'setup.py\', script_args=(\'--dry-run\',), stop_after=\'config\');skip_keys = (\'cmdclass\', \'distclass\', \'ext_modules\', \'metadata\');data = {    key: value for key, value in dist.__dict__.items()     if (        not key.startswith(\'_\') and         not callable(value) and         key not in skip_keys and         key not in dist.display_option_names    )};data[\'metadata\'] = {    k: v for k, v in dist.metadata.__dict__.items()     if k not in (\'license_files\', \'provides_extras\')};sys.stdout.buffer.write(repr(data).encode(\'utf-8\'))']' returned non-zero exit status 1.

Traceback (most recent call last):
  File "<string>", line 1, in <module>
  File "/usr/lib/python3.10/distutils/core.py", line 225, in run_setup
    raise RuntimeError(("'distutils.core.setup()' was never called -- "
RuntimeError: 'distutils.core.setup()' was never called -- perhaps 'setup.py' is not a Distutils setup script?
[3.501s] ERROR:colcon.colcon_core.package_identification:Exception in package identification extension 'python_setup_py' in 'lib/python3/dist-packages/numpy/f2py': Command '['/usr/bin/python3', '-c', 'import sys;from contextlib import suppress;exec("with suppress(ImportError):    from setuptools.extern.packaging.specifiers    import SpecifierSet");exec("with suppress(ImportError):    from packaging.specifiers import SpecifierSet");from distutils.core import run_setup;dist = run_setup(    \'setup.py\', script_args=(\'--dry-run\',), stop_after=\'config\');skip_keys = (\'cmdclass\', \'distclass\', \'ext_modules\', \'metadata\');data = {    key: value for key, value in dist.__dict__.items()     if (        not key.startswith(\'_\') and         not callable(value) and         key not in skip_keys and         key not in dist.display_option_names    )};data[\'metadata\'] = {    k: v for k, v in dist.metadata.__dict__.items()     if k not in (\'license_files\', \'provides_extras\')};sys.stdout.buffer.write(repr(data).encode(\'utf-8\'))']' returned non-zero exit status 1.
Traceback (most recent call last):
  File "/usr/lib/python3/dist-packages/colcon_core/package_identification/__init__.py", line 142, in _identify
    retval = extension.identify(_reused_descriptor_instance)
  File "/usr/lib/python3/dist-packages/colcon_python_setup_py/package_identification/python_setup_py.py", line 48, in identify
    config = get_setup_information(setup_py)
  File "/usr/lib/python3/dist-packages/colcon_python_setup_py/package_identification/python_setup_py.py", line 241, in get_setup_information
    _setup_information_cache[hashable_env] = _get_setup_information(
  File "/usr/lib/python3/dist-packages/colcon_python_setup_py/package_identification/python_setup_py.py", line 288, in _get_setup_information
    result = subprocess.run(
  File "/usr/lib/python3.10/subprocess.py", line 526, in run
    raise CalledProcessError(retcode, process.args,
subprocess.CalledProcessError: Command '['/usr/bin/python3', '-c', 'import sys;from contextlib import suppress;exec("with suppress(ImportError):    from setuptools.extern.packaging.specifiers    import SpecifierSet");exec("with suppress(ImportError):    from packaging.specifiers import SpecifierSet");from distutils.core import run_setup;dist = run_setup(    \'setup.py\', script_args=(\'--dry-run\',), stop_after=\'config\');skip_keys = (\'cmdclass\', \'distclass\', \'ext_modules\', \'metadata\');data = {    key: value for key, value in dist.__dict__.items()     if (        not key.startswith(\'_\') and         not callable(value) and         key not in skip_keys and         key not in dist.display_option_names    )};data[\'metadata\'] = {    k: v for k, v in dist.metadata.__dict__.items()     if k not in (\'license_files\', \'provides_extras\')};sys.stdout.buffer.write(repr(data).encode(\'utf-8\'))']' returned non-zero exit status 1.

Traceback (most recent call last):
  File "<string>", line 1, in <module>
  File "/usr/lib/python3.10/distutils/core.py", line 225, in run_setup
    raise RuntimeError(("'distutils.core.setup()' was never called -- "
RuntimeError: 'distutils.core.setup()' was never called -- perhaps 'setup.py' is not a Distutils setup script?
[3.788s] ERROR:colcon.colcon_core.package_identification:Exception in package identification extension 'python_setup_py' in 'lib/python3/dist-packages/numpy/fft': Command '['/usr/bin/python3', '-c', 'import sys;from contextlib import suppress;exec("with suppress(ImportError):    from setuptools.extern.packaging.specifiers    import SpecifierSet");exec("with suppress(ImportError):    from packaging.specifiers import SpecifierSet");from distutils.core import run_setup;dist = run_setup(    \'setup.py\', script_args=(\'--dry-run\',), stop_after=\'config\');skip_keys = (\'cmdclass\', \'distclass\', \'ext_modules\', \'metadata\');data = {    key: value for key, value in dist.__dict__.items()     if (        not key.startswith(\'_\') and         not callable(value) and         key not in skip_keys and         key not in dist.display_option_names    )};data[\'metadata\'] = {    k: v for k, v in dist.metadata.__dict__.items()     if k not in (\'license_files\', \'provides_extras\')};sys.stdout.buffer.write(repr(data).encode(\'utf-8\'))']' returned non-zero exit status 1.
Traceback (most recent call last):
  File "/usr/lib/python3/dist-packages/colcon_core/package_identification/__init__.py", line 142, in _identify
    retval = extension.identify(_reused_descriptor_instance)
  File "/usr/lib/python3/dist-packages/colcon_python_setup_py/package_identification/python_setup_py.py", line 48, in identify
    config = get_setup_information(setup_py)
  File "/usr/lib/python3/dist-packages/colcon_python_setup_py/package_identification/python_setup_py.py", line 241, in get_setup_information
    _setup_information_cache[hashable_env] = _get_setup_information(
  File "/usr/lib/python3/dist-packages/colcon_python_setup_py/package_identification/python_setup_py.py", line 288, in _get_setup_information
    result = subprocess.run(
  File "/usr/lib/python3.10/subprocess.py", line 526, in run
    raise CalledProcessError(retcode, process.args,
subprocess.CalledProcessError: Command '['/usr/bin/python3', '-c', 'import sys;from contextlib import suppress;exec("with suppress(ImportError):    from setuptools.extern.packaging.specifiers    import SpecifierSet");exec("with suppress(ImportError):    from packaging.specifiers import SpecifierSet");from distutils.core import run_setup;dist = run_setup(    \'setup.py\', script_args=(\'--dry-run\',), stop_after=\'config\');skip_keys = (\'cmdclass\', \'distclass\', \'ext_modules\', \'metadata\');data = {    key: value for key, value in dist.__dict__.items()     if (        not key.startswith(\'_\') and         not callable(value) and         key not in skip_keys and         key not in dist.display_option_names    )};data[\'metadata\'] = {    k: v for k, v in dist.metadata.__dict__.items()     if k not in (\'license_files\', \'provides_extras\')};sys.stdout.buffer.write(repr(data).encode(\'utf-8\'))']' returned non-zero exit status 1.

Traceback (most recent call last):
  File "<string>", line 1, in <module>
  File "/usr/lib/python3.10/distutils/core.py", line 225, in run_setup
    raise RuntimeError(("'distutils.core.setup()' was never called -- "
RuntimeError: 'distutils.core.setup()' was never called -- perhaps 'setup.py' is not a Distutils setup script?
[4.061s] ERROR:colcon.colcon_core.package_identification:Exception in package identification extension 'python_setup_py' in 'lib/python3/dist-packages/numpy/lib': Command '['/usr/bin/python3', '-c', 'import sys;from contextlib import suppress;exec("with suppress(ImportError):    from setuptools.extern.packaging.specifiers    import SpecifierSet");exec("with suppress(ImportError):    from packaging.specifiers import SpecifierSet");from distutils.core import run_setup;dist = run_setup(    \'setup.py\', script_args=(\'--dry-run\',), stop_after=\'config\');skip_keys = (\'cmdclass\', \'distclass\', \'ext_modules\', \'metadata\');data = {    key: value for key, value in dist.__dict__.items()     if (        not key.startswith(\'_\') and         not callable(value) and         key not in skip_keys and         key not in dist.display_option_names    )};data[\'metadata\'] = {    k: v for k, v in dist.metadata.__dict__.items()     if k not in (\'license_files\', \'provides_extras\')};sys.stdout.buffer.write(repr(data).encode(\'utf-8\'))']' returned non-zero exit status 1.
Traceback (most recent call last):
  File "/usr/lib/python3/dist-packages/colcon_core/package_identification/__init__.py", line 142, in _identify
    retval = extension.identify(_reused_descriptor_instance)
  File "/usr/lib/python3/dist-packages/colcon_python_setup_py/package_identification/python_setup_py.py", line 48, in identify
    config = get_setup_information(setup_py)
  File "/usr/lib/python3/dist-packages/colcon_python_setup_py/package_identification/python_setup_py.py", line 241, in get_setup_information
    _setup_information_cache[hashable_env] = _get_setup_information(
  File "/usr/lib/python3/dist-packages/colcon_python_setup_py/package_identification/python_setup_py.py", line 288, in _get_setup_information
    result = subprocess.run(
  File "/usr/lib/python3.10/subprocess.py", line 526, in run
    raise CalledProcessError(retcode, process.args,
subprocess.CalledProcessError: Command '['/usr/bin/python3', '-c', 'import sys;from contextlib import suppress;exec("with suppress(ImportError):    from setuptools.extern.packaging.specifiers    import SpecifierSet");exec("with suppress(ImportError):    from packaging.specifiers import SpecifierSet");from distutils.core import run_setup;dist = run_setup(    \'setup.py\', script_args=(\'--dry-run\',), stop_after=\'config\');skip_keys = (\'cmdclass\', \'distclass\', \'ext_modules\', \'metadata\');data = {    key: value for key, value in dist.__dict__.items()     if (        not key.startswith(\'_\') and         not callable(value) and         key not in skip_keys and         key not in dist.display_option_names    )};data[\'metadata\'] = {    k: v for k, v in dist.metadata.__dict__.items()     if k not in (\'license_files\', \'provides_extras\')};sys.stdout.buffer.write(repr(data).encode(\'utf-8\'))']' returned non-zero exit status 1.

Traceback (most recent call last):
  File "<string>", line 1, in <module>
  File "/usr/lib/python3.10/distutils/core.py", line 225, in run_setup
    raise RuntimeError(("'distutils.core.setup()' was never called -- "
RuntimeError: 'distutils.core.setup()' was never called -- perhaps 'setup.py' is not a Distutils setup script?
[4.317s] ERROR:colcon.colcon_core.package_identification:Exception in package identification extension 'python_setup_py' in 'lib/python3/dist-packages/numpy/linalg': Command '['/usr/bin/python3', '-c', 'import sys;from contextlib import suppress;exec("with suppress(ImportError):    from setuptools.extern.packaging.specifiers    import SpecifierSet");exec("with suppress(ImportError):    from packaging.specifiers import SpecifierSet");from distutils.core import run_setup;dist = run_setup(    \'setup.py\', script_args=(\'--dry-run\',), stop_after=\'config\');skip_keys = (\'cmdclass\', \'distclass\', \'ext_modules\', \'metadata\');data = {    key: value for key, value in dist.__dict__.items()     if (        not key.startswith(\'_\') and         not callable(value) and         key not in skip_keys and         key not in dist.display_option_names    )};data[\'metadata\'] = {    k: v for k, v in dist.metadata.__dict__.items()     if k not in (\'license_files\', \'provides_extras\')};sys.stdout.buffer.write(repr(data).encode(\'utf-8\'))']' returned non-zero exit status 1.
Traceback (most recent call last):
  File "/usr/lib/python3/dist-packages/colcon_core/package_identification/__init__.py", line 142, in _identify
    retval = extension.identify(_reused_descriptor_instance)
  File "/usr/lib/python3/dist-packages/colcon_python_setup_py/package_identification/python_setup_py.py", line 48, in identify
    config = get_setup_information(setup_py)
  File "/usr/lib/python3/dist-packages/colcon_python_setup_py/package_identification/python_setup_py.py", line 241, in get_setup_information
    _setup_information_cache[hashable_env] = _get_setup_information(
  File "/usr/lib/python3/dist-packages/colcon_python_setup_py/package_identification/python_setup_py.py", line 288, in _get_setup_information
    result = subprocess.run(
  File "/usr/lib/python3.10/subprocess.py", line 526, in run
    raise CalledProcessError(retcode, process.args,
subprocess.CalledProcessError: Command '['/usr/bin/python3', '-c', 'import sys;from contextlib import suppress;exec("with suppress(ImportError):    from setuptools.extern.packaging.specifiers    import SpecifierSet");exec("with suppress(ImportError):    from packaging.specifiers import SpecifierSet");from distutils.core import run_setup;dist = run_setup(    \'setup.py\', script_args=(\'--dry-run\',), stop_after=\'config\');skip_keys = (\'cmdclass\', \'distclass\', \'ext_modules\', \'metadata\');data = {    key: value for key, value in dist.__dict__.items()     if (        not key.startswith(\'_\') and         not callable(value) and         key not in skip_keys and         key not in dist.display_option_names    )};data[\'metadata\'] = {    k: v for k, v in dist.metadata.__dict__.items()     if k not in (\'license_files\', \'provides_extras\')};sys.stdout.buffer.write(repr(data).encode(\'utf-8\'))']' returned non-zero exit status 1.

Traceback (most recent call last):
  File "<string>", line 1, in <module>
  File "/usr/lib/python3.10/distutils/core.py", line 225, in run_setup
    raise RuntimeError(("'distutils.core.setup()' was never called -- "
RuntimeError: 'distutils.core.setup()' was never called -- perhaps 'setup.py' is not a Distutils setup script?
[4.576s] ERROR:colcon.colcon_core.package_identification:Exception in package identification extension 'python_setup_py' in 'lib/python3/dist-packages/numpy/ma': Command '['/usr/bin/python3', '-c', 'import sys;from contextlib import suppress;exec("with suppress(ImportError):    from setuptools.extern.packaging.specifiers    import SpecifierSet");exec("with suppress(ImportError):    from packaging.specifiers import SpecifierSet");from distutils.core import run_setup;dist = run_setup(    \'setup.py\', script_args=(\'--dry-run\',), stop_after=\'config\');skip_keys = (\'cmdclass\', \'distclass\', \'ext_modules\', \'metadata\');data = {    key: value for key, value in dist.__dict__.items()     if (        not key.startswith(\'_\') and         not callable(value) and         key not in skip_keys and         key not in dist.display_option_names    )};data[\'metadata\'] = {    k: v for k, v in dist.metadata.__dict__.items()     if k not in (\'license_files\', \'provides_extras\')};sys.stdout.buffer.write(repr(data).encode(\'utf-8\'))']' returned non-zero exit status 1.
Traceback (most recent call last):
  File "/usr/lib/python3/dist-packages/colcon_core/package_identification/__init__.py", line 142, in _identify
    retval = extension.identify(_reused_descriptor_instance)
  File "/usr/lib/python3/dist-packages/colcon_python_setup_py/package_identification/python_setup_py.py", line 48, in identify
    config = get_setup_information(setup_py)
  File "/usr/lib/python3/dist-packages/colcon_python_setup_py/package_identification/python_setup_py.py", line 241, in get_setup_information
    _setup_information_cache[hashable_env] = _get_setup_information(
  File "/usr/lib/python3/dist-packages/colcon_python_setup_py/package_identification/python_setup_py.py", line 288, in _get_setup_information
    result = subprocess.run(
  File "/usr/lib/python3.10/subprocess.py", line 526, in run
    raise CalledProcessError(retcode, process.args,
subprocess.CalledProcessError: Command '['/usr/bin/python3', '-c', 'import sys;from contextlib import suppress;exec("with suppress(ImportError):    from setuptools.extern.packaging.specifiers    import SpecifierSet");exec("with suppress(ImportError):    from packaging.specifiers import SpecifierSet");from distutils.core import run_setup;dist = run_setup(    \'setup.py\', script_args=(\'--dry-run\',), stop_after=\'config\');skip_keys = (\'cmdclass\', \'distclass\', \'ext_modules\', \'metadata\');data = {    key: value for key, value in dist.__dict__.items()     if (        not key.startswith(\'_\') and         not callable(value) and         key not in skip_keys and         key not in dist.display_option_names    )};data[\'metadata\'] = {    k: v for k, v in dist.metadata.__dict__.items()     if k not in (\'license_files\', \'provides_extras\')};sys.stdout.buffer.write(repr(data).encode(\'utf-8\'))']' returned non-zero exit status 1.

Traceback (most recent call last):
  File "<string>", line 1, in <module>
  File "/usr/lib/python3.10/distutils/core.py", line 225, in run_setup
    raise RuntimeError(("'distutils.core.setup()' was never called -- "
RuntimeError: 'distutils.core.setup()' was never called -- perhaps 'setup.py' is not a Distutils setup script?
[4.830s] ERROR:colcon.colcon_core.package_identification:Exception in package identification extension 'python_setup_py' in 'lib/python3/dist-packages/numpy/matrixlib': Command '['/usr/bin/python3', '-c', 'import sys;from contextlib import suppress;exec("with suppress(ImportError):    from setuptools.extern.packaging.specifiers    import SpecifierSet");exec("with suppress(ImportError):    from packaging.specifiers import SpecifierSet");from distutils.core import run_setup;dist = run_setup(    \'setup.py\', script_args=(\'--dry-run\',), stop_after=\'config\');skip_keys = (\'cmdclass\', \'distclass\', \'ext_modules\', \'metadata\');data = {    key: value for key, value in dist.__dict__.items()     if (        not key.startswith(\'_\') and         not callable(value) and         key not in skip_keys and         key not in dist.display_option_names    )};data[\'metadata\'] = {    k: v for k, v in dist.metadata.__dict__.items()     if k not in (\'license_files\', \'provides_extras\')};sys.stdout.buffer.write(repr(data).encode(\'utf-8\'))']' returned non-zero exit status 1.
Traceback (most recent call last):
  File "/usr/lib/python3/dist-packages/colcon_core/package_identification/__init__.py", line 142, in _identify
    retval = extension.identify(_reused_descriptor_instance)
  File "/usr/lib/python3/dist-packages/colcon_python_setup_py/package_identification/python_setup_py.py", line 48, in identify
    config = get_setup_information(setup_py)
  File "/usr/lib/python3/dist-packages/colcon_python_setup_py/package_identification/python_setup_py.py", line 241, in get_setup_information
    _setup_information_cache[hashable_env] = _get_setup_information(
  File "/usr/lib/python3/dist-packages/colcon_python_setup_py/package_identification/python_setup_py.py", line 288, in _get_setup_information
    result = subprocess.run(
  File "/usr/lib/python3.10/subprocess.py", line 526, in run
    raise CalledProcessError(retcode, process.args,
subprocess.CalledProcessError: Command '['/usr/bin/python3', '-c', 'import sys;from contextlib import suppress;exec("with suppress(ImportError):    from setuptools.extern.packaging.specifiers    import SpecifierSet");exec("with suppress(ImportError):    from packaging.specifiers import SpecifierSet");from distutils.core import run_setup;dist = run_setup(    \'setup.py\', script_args=(\'--dry-run\',), stop_after=\'config\');skip_keys = (\'cmdclass\', \'distclass\', \'ext_modules\', \'metadata\');data = {    key: value for key, value in dist.__dict__.items()     if (        not key.startswith(\'_\') and         not callable(value) and         key not in skip_keys and         key not in dist.display_option_names    )};data[\'metadata\'] = {    k: v for k, v in dist.metadata.__dict__.items()     if k not in (\'license_files\', \'provides_extras\')};sys.stdout.buffer.write(repr(data).encode(\'utf-8\'))']' returned non-zero exit status 1.

Traceback (most recent call last):
  File "<string>", line 1, in <module>
  File "/usr/lib/python3.10/distutils/core.py", line 225, in run_setup
    raise RuntimeError(("'distutils.core.setup()' was never called -- "
RuntimeError: 'distutils.core.setup()' was never called -- perhaps 'setup.py' is not a Distutils setup script?
[5.109s] ERROR:colcon.colcon_core.package_identification:Exception in package identification extension 'python_setup_py' in 'lib/python3/dist-packages/numpy/polynomial': Command '['/usr/bin/python3', '-c', 'import sys;from contextlib import suppress;exec("with suppress(ImportError):    from setuptools.extern.packaging.specifiers    import SpecifierSet");exec("with suppress(ImportError):    from packaging.specifiers import SpecifierSet");from distutils.core import run_setup;dist = run_setup(    \'setup.py\', script_args=(\'--dry-run\',), stop_after=\'config\');skip_keys = (\'cmdclass\', \'distclass\', \'ext_modules\', \'metadata\');data = {    key: value for key, value in dist.__dict__.items()     if (        not key.startswith(\'_\') and         not callable(value) and         key not in skip_keys and         key not in dist.display_option_names    )};data[\'metadata\'] = {    k: v for k, v in dist.metadata.__dict__.items()     if k not in (\'license_files\', \'provides_extras\')};sys.stdout.buffer.write(repr(data).encode(\'utf-8\'))']' returned non-zero exit status 1.
Traceback (most recent call last):
  File "/usr/lib/python3/dist-packages/colcon_core/package_identification/__init__.py", line 142, in _identify
    retval = extension.identify(_reused_descriptor_instance)
  File "/usr/lib/python3/dist-packages/colcon_python_setup_py/package_identification/python_setup_py.py", line 48, in identify
    config = get_setup_information(setup_py)
  File "/usr/lib/python3/dist-packages/colcon_python_setup_py/package_identification/python_setup_py.py", line 241, in get_setup_information
    _setup_information_cache[hashable_env] = _get_setup_information(
  File "/usr/lib/python3/dist-packages/colcon_python_setup_py/package_identification/python_setup_py.py", line 288, in _get_setup_information
    result = subprocess.run(
  File "/usr/lib/python3.10/subprocess.py", line 526, in run
    raise CalledProcessError(retcode, process.args,
subprocess.CalledProcessError: Command '['/usr/bin/python3', '-c', 'import sys;from contextlib import suppress;exec("with suppress(ImportError):    from setuptools.extern.packaging.specifiers    import SpecifierSet");exec("with suppress(ImportError):    from packaging.specifiers import SpecifierSet");from distutils.core import run_setup;dist = run_setup(    \'setup.py\', script_args=(\'--dry-run\',), stop_after=\'config\');skip_keys = (\'cmdclass\', \'distclass\', \'ext_modules\', \'metadata\');data = {    key: value for key, value in dist.__dict__.items()     if (        not key.startswith(\'_\') and         not callable(value) and         key not in skip_keys and         key not in dist.display_option_names    )};data[\'metadata\'] = {    k: v for k, v in dist.metadata.__dict__.items()     if k not in (\'license_files\', \'provides_extras\')};sys.stdout.buffer.write(repr(data).encode(\'utf-8\'))']' returned non-zero exit status 1.

Traceback (most recent call last):
  File "<string>", line 1, in <module>
  File "/usr/lib/python3.10/distutils/core.py", line 225, in run_setup
    raise RuntimeError(("'distutils.core.setup()' was never called -- "
RuntimeError: 'distutils.core.setup()' was never called -- perhaps 'setup.py' is not a Distutils setup script?
[5.493s] ERROR:colcon.colcon_core.package_identification:Exception in package identification extension 'python_setup_py' in 'lib/python3/dist-packages/numpy/random': Command '['/usr/bin/python3', '-c', 'import sys;from contextlib import suppress;exec("with suppress(ImportError):    from setuptools.extern.packaging.specifiers    import SpecifierSet");exec("with suppress(ImportError):    from packaging.specifiers import SpecifierSet");from distutils.core import run_setup;dist = run_setup(    \'setup.py\', script_args=(\'--dry-run\',), stop_after=\'config\');skip_keys = (\'cmdclass\', \'distclass\', \'ext_modules\', \'metadata\');data = {    key: value for key, value in dist.__dict__.items()     if (        not key.startswith(\'_\') and         not callable(value) and         key not in skip_keys and         key not in dist.display_option_names    )};data[\'metadata\'] = {    k: v for k, v in dist.metadata.__dict__.items()     if k not in (\'license_files\', \'provides_extras\')};sys.stdout.buffer.write(repr(data).encode(\'utf-8\'))']' returned non-zero exit status 1.
Traceback (most recent call last):
  File "/usr/lib/python3/dist-packages/colcon_core/package_identification/__init__.py", line 142, in _identify
    retval = extension.identify(_reused_descriptor_instance)
  File "/usr/lib/python3/dist-packages/colcon_python_setup_py/package_identification/python_setup_py.py", line 48, in identify
    config = get_setup_information(setup_py)
  File "/usr/lib/python3/dist-packages/colcon_python_setup_py/package_identification/python_setup_py.py", line 241, in get_setup_information
    _setup_information_cache[hashable_env] = _get_setup_information(
  File "/usr/lib/python3/dist-packages/colcon_python_setup_py/package_identification/python_setup_py.py", line 288, in _get_setup_information
    result = subprocess.run(
  File "/usr/lib/python3.10/subprocess.py", line 526, in run
    raise CalledProcessError(retcode, process.args,
subprocess.CalledProcessError: Command '['/usr/bin/python3', '-c', 'import sys;from contextlib import suppress;exec("with suppress(ImportError):    from setuptools.extern.packaging.specifiers    import SpecifierSet");exec("with suppress(ImportError):    from packaging.specifiers import SpecifierSet");from distutils.core import run_setup;dist = run_setup(    \'setup.py\', script_args=(\'--dry-run\',), stop_after=\'config\');skip_keys = (\'cmdclass\', \'distclass\', \'ext_modules\', \'metadata\');data = {    key: value for key, value in dist.__dict__.items()     if (        not key.startswith(\'_\') and         not callable(value) and         key not in skip_keys and         key not in dist.display_option_names    )};data[\'metadata\'] = {    k: v for k, v in dist.metadata.__dict__.items()     if k not in (\'license_files\', \'provides_extras\')};sys.stdout.buffer.write(repr(data).encode(\'utf-8\'))']' returned non-zero exit status 1.

Traceback (most recent call last):
  File "<string>", line 1, in <module>
  File "/usr/lib/python3.10/distutils/core.py", line 215, in run_setup
    exec(f.read(), g)
  File "<string>", line 11, in <module>
ModuleNotFoundError: No module named 'Cython'
[5.844s] ERROR:colcon.colcon_core.package_identification:Exception in package identification extension 'python_setup_py' in 'lib/python3/dist-packages/numpy/random/_examples/cython': Command '['/usr/bin/python3', '-c', 'import sys;from contextlib import suppress;exec("with suppress(ImportError):    from setuptools.extern.packaging.specifiers    import SpecifierSet");exec("with suppress(ImportError):    from packaging.specifiers import SpecifierSet");from distutils.core import run_setup;dist = run_setup(    \'setup.py\', script_args=(\'--dry-run\',), stop_after=\'config\');skip_keys = (\'cmdclass\', \'distclass\', \'ext_modules\', \'metadata\');data = {    key: value for key, value in dist.__dict__.items()     if (        not key.startswith(\'_\') and         not callable(value) and         key not in skip_keys and         key not in dist.display_option_names    )};data[\'metadata\'] = {    k: v for k, v in dist.metadata.__dict__.items()     if k not in (\'license_files\', \'provides_extras\')};sys.stdout.buffer.write(repr(data).encode(\'utf-8\'))']' returned non-zero exit status 1.
Traceback (most recent call last):
  File "/usr/lib/python3/dist-packages/colcon_core/package_identification/__init__.py", line 142, in _identify
    retval = extension.identify(_reused_descriptor_instance)
  File "/usr/lib/python3/dist-packages/colcon_python_setup_py/package_identification/python_setup_py.py", line 48, in identify
    config = get_setup_information(setup_py)
  File "/usr/lib/python3/dist-packages/colcon_python_setup_py/package_identification/python_setup_py.py", line 241, in get_setup_information
    _setup_information_cache[hashable_env] = _get_setup_information(
  File "/usr/lib/python3/dist-packages/colcon_python_setup_py/package_identification/python_setup_py.py", line 288, in _get_setup_information
    result = subprocess.run(
  File "/usr/lib/python3.10/subprocess.py", line 526, in run
    raise CalledProcessError(retcode, process.args,
subprocess.CalledProcessError: Command '['/usr/bin/python3', '-c', 'import sys;from contextlib import suppress;exec("with suppress(ImportError):    from setuptools.extern.packaging.specifiers    import SpecifierSet");exec("with suppress(ImportError):    from packaging.specifiers import SpecifierSet");from distutils.core import run_setup;dist = run_setup(    \'setup.py\', script_args=(\'--dry-run\',), stop_after=\'config\');skip_keys = (\'cmdclass\', \'distclass\', \'ext_modules\', \'metadata\');data = {    key: value for key, value in dist.__dict__.items()     if (        not key.startswith(\'_\') and         not callable(value) and         key not in skip_keys and         key not in dist.display_option_names    )};data[\'metadata\'] = {    k: v for k, v in dist.metadata.__dict__.items()     if k not in (\'license_files\', \'provides_extras\')};sys.stdout.buffer.write(repr(data).encode(\'utf-8\'))']' returned non-zero exit status 1.

Traceback (most recent call last):
  File "<string>", line 1, in <module>
  File "/usr/lib/python3.10/distutils/core.py", line 225, in run_setup
    raise RuntimeError(("'distutils.core.setup()' was never called -- "
RuntimeError: 'distutils.core.setup()' was never called -- perhaps 'setup.py' is not a Distutils setup script?
[6.107s] ERROR:colcon.colcon_core.package_identification:Exception in package identification extension 'python_setup_py' in 'lib/python3/dist-packages/numpy/testing': Command '['/usr/bin/python3', '-c', 'import sys;from contextlib import suppress;exec("with suppress(ImportError):    from setuptools.extern.packaging.specifiers    import SpecifierSet");exec("with suppress(ImportError):    from packaging.specifiers import SpecifierSet");from distutils.core import run_setup;dist = run_setup(    \'setup.py\', script_args=(\'--dry-run\',), stop_after=\'config\');skip_keys = (\'cmdclass\', \'distclass\', \'ext_modules\', \'metadata\');data = {    key: value for key, value in dist.__dict__.items()     if (        not key.startswith(\'_\') and         not callable(value) and         key not in skip_keys and         key not in dist.display_option_names    )};data[\'metadata\'] = {    k: v for k, v in dist.metadata.__dict__.items()     if k not in (\'license_files\', \'provides_extras\')};sys.stdout.buffer.write(repr(data).encode(\'utf-8\'))']' returned non-zero exit status 1.
Traceback (most recent call last):
  File "/usr/lib/python3/dist-packages/colcon_core/package_identification/__init__.py", line 142, in _identify
    retval = extension.identify(_reused_descriptor_instance)
  File "/usr/lib/python3/dist-packages/colcon_python_setup_py/package_identification/python_setup_py.py", line 48, in identify
    config = get_setup_information(setup_py)
  File "/usr/lib/python3/dist-packages/colcon_python_setup_py/package_identification/python_setup_py.py", line 241, in get_setup_information
    _setup_information_cache[hashable_env] = _get_setup_information(
  File "/usr/lib/python3/dist-packages/colcon_python_setup_py/package_identification/python_setup_py.py", line 288, in _get_setup_information
    result = subprocess.run(
  File "/usr/lib/python3.10/subprocess.py", line 526, in run
    raise CalledProcessError(retcode, process.args,
subprocess.CalledProcessError: Command '['/usr/bin/python3', '-c', 'import sys;from contextlib import suppress;exec("with suppress(ImportError):    from setuptools.extern.packaging.specifiers    import SpecifierSet");exec("with suppress(ImportError):    from packaging.specifiers import SpecifierSet");from distutils.core import run_setup;dist = run_setup(    \'setup.py\', script_args=(\'--dry-run\',), stop_after=\'config\');skip_keys = (\'cmdclass\', \'distclass\', \'ext_modules\', \'metadata\');data = {    key: value for key, value in dist.__dict__.items()     if (        not key.startswith(\'_\') and         not callable(value) and         key not in skip_keys and         key not in dist.display_option_names    )};data[\'metadata\'] = {    k: v for k, v in dist.metadata.__dict__.items()     if k not in (\'license_files\', \'provides_extras\')};sys.stdout.buffer.write(repr(data).encode(\'utf-8\'))']' returned non-zero exit status 1.

Traceback (most recent call last):
  File "<string>", line 1, in <module>
  File "/usr/lib/python3.10/distutils/core.py", line 225, in run_setup
    raise RuntimeError(("'distutils.core.setup()' was never called -- "
RuntimeError: 'distutils.core.setup()' was never called -- perhaps 'setup.py' is not a Distutils setup script?
[6.389s] ERROR:colcon.colcon_core.package_identification:Exception in package identification extension 'python_setup_py' in 'lib/python3/dist-packages/numpy/typing': Command '['/usr/bin/python3', '-c', 'import sys;from contextlib import suppress;exec("with suppress(ImportError):    from setuptools.extern.packaging.specifiers    import SpecifierSet");exec("with suppress(ImportError):    from packaging.specifiers import SpecifierSet");from distutils.core import run_setup;dist = run_setup(    \'setup.py\', script_args=(\'--dry-run\',), stop_after=\'config\');skip_keys = (\'cmdclass\', \'distclass\', \'ext_modules\', \'metadata\');data = {    key: value for key, value in dist.__dict__.items()     if (        not key.startswith(\'_\') and         not callable(value) and         key not in skip_keys and         key not in dist.display_option_names    )};data[\'metadata\'] = {    k: v for k, v in dist.metadata.__dict__.items()     if k not in (\'license_files\', \'provides_extras\')};sys.stdout.buffer.write(repr(data).encode(\'utf-8\'))']' returned non-zero exit status 1.
Traceback (most recent call last):
  File "/usr/lib/python3/dist-packages/colcon_core/package_identification/__init__.py", line 142, in _identify
    retval = extension.identify(_reused_descriptor_instance)
  File "/usr/lib/python3/dist-packages/colcon_python_setup_py/package_identification/python_setup_py.py", line 48, in identify
    config = get_setup_information(setup_py)
  File "/usr/lib/python3/dist-packages/colcon_python_setup_py/package_identification/python_setup_py.py", line 241, in get_setup_information
    _setup_information_cache[hashable_env] = _get_setup_information(
  File "/usr/lib/python3/dist-packages/colcon_python_setup_py/package_identification/python_setup_py.py", line 288, in _get_setup_information
    result = subprocess.run(
  File "/usr/lib/python3.10/subprocess.py", line 526, in run
    raise CalledProcessError(retcode, process.args,
subprocess.CalledProcessError: Command '['/usr/bin/python3', '-c', 'import sys;from contextlib import suppress;exec("with suppress(ImportError):    from setuptools.extern.packaging.specifiers    import SpecifierSet");exec("with suppress(ImportError):    from packaging.specifiers import SpecifierSet");from distutils.core import run_setup;dist = run_setup(    \'setup.py\', script_args=(\'--dry-run\',), stop_after=\'config\');skip_keys = (\'cmdclass\', \'distclass\', \'ext_modules\', \'metadata\');data = {    key: value for key, value in dist.__dict__.items()     if (        not key.startswith(\'_\') and         not callable(value) and         key not in skip_keys and         key not in dist.display_option_names    )};data[\'metadata\'] = {    k: v for k, v in dist.metadata.__dict__.items()     if k not in (\'license_files\', \'provides_extras\')};sys.stdout.buffer.write(repr(data).encode(\'utf-8\'))']' returned non-zero exit status 1.

Traceback (most recent call last):
  File "<string>", line 1, in <module>
  File "/usr/lib/python3.10/distutils/core.py", line 225, in run_setup
    raise RuntimeError(("'distutils.core.setup()' was never called -- "
RuntimeError: 'distutils.core.setup()' was never called -- perhaps 'setup.py' is not a Distutils setup script?
[7.844s] ERROR:colcon.colcon_core.package_identification:Exception in package identification extension 'python_setup_py' in 'lib/python3.10/test/libregrtest': Command '['/usr/bin/python3', '-c', 'import sys;from contextlib import suppress;exec("with suppress(ImportError):    from setuptools.extern.packaging.specifiers    import SpecifierSet");exec("with suppress(ImportError):    from packaging.specifiers import SpecifierSet");from distutils.core import run_setup;dist = run_setup(    \'setup.py\', script_args=(\'--dry-run\',), stop_after=\'config\');skip_keys = (\'cmdclass\', \'distclass\', \'ext_modules\', \'metadata\');data = {    key: value for key, value in dist.__dict__.items()     if (        not key.startswith(\'_\') and         not callable(value) and         key not in skip_keys and         key not in dist.display_option_names    )};data[\'metadata\'] = {    k: v for k, v in dist.metadata.__dict__.items()     if k not in (\'license_files\', \'provides_extras\')};sys.stdout.buffer.write(repr(data).encode(\'utf-8\'))']' returned non-zero exit status 1.
Traceback (most recent call last):
  File "/usr/lib/python3/dist-packages/colcon_core/package_identification/__init__.py", line 142, in _identify
    retval = extension.identify(_reused_descriptor_instance)
  File "/usr/lib/python3/dist-packages/colcon_python_setup_py/package_identification/python_setup_py.py", line 48, in identify
    config = get_setup_information(setup_py)
  File "/usr/lib/python3/dist-packages/colcon_python_setup_py/package_identification/python_setup_py.py", line 241, in get_setup_information
    _setup_information_cache[hashable_env] = _get_setup_information(
  File "/usr/lib/python3/dist-packages/colcon_python_setup_py/package_identification/python_setup_py.py", line 288, in _get_setup_information
    result = subprocess.run(
  File "/usr/lib/python3.10/subprocess.py", line 526, in run
    raise CalledProcessError(retcode, process.args,
subprocess.CalledProcessError: Command '['/usr/bin/python3', '-c', 'import sys;from contextlib import suppress;exec("with suppress(ImportError):    from setuptools.extern.packaging.specifiers    import SpecifierSet");exec("with suppress(ImportError):    from packaging.specifiers import SpecifierSet");from distutils.core import run_setup;dist = run_setup(    \'setup.py\', script_args=(\'--dry-run\',), stop_after=\'config\');skip_keys = (\'cmdclass\', \'distclass\', \'ext_modules\', \'metadata\');data = {    key: value for key, value in dist.__dict__.items()     if (        not key.startswith(\'_\') and         not callable(value) and         key not in skip_keys and         key not in dist.display_option_names    )};data[\'metadata\'] = {    k: v for k, v in dist.metadata.__dict__.items()     if k not in (\'license_files\', \'provides_extras\')};sys.stdout.buffer.write(repr(data).encode(\'utf-8\'))']' returned non-zero exit status 1.

[20.755s] ERROR:colcon:colcon build: Duplicate package names not supported:
- gmock:
  - opt/ros/humble/src/gmock_vendor
  - usr/src/gmock
- gtest:
  - opt/ros/humble/src/gtest_vendor
  - usr/src/gtest
building at STEP "RUN . /usr/share/gazebo/setup.sh && . /opt/ros/humble/setup.sh     && mkdir /root/turtlebot3_ws     && git clone -b humble-devel https://github.com/ROBOTIS-GIT/turtlebot3_simulations.git src     && colcon build --symlink-install": while running runtime: exit status 1

Error: executing /usr/local/bin/docker-compose build: exit status 1
